Workbook
Name Activity_Level: #REF!
Name Activity_Level: #REF!
Name Activity_Level: #REF!
Name Activity_Level: #REF!
Name x: #REF!
Name x: #REF!
Name x: #REF!

Sheet Cover
B2: ANDROMEDA STAFF BADGE-CURRENT CHARACTERISATION DOCUMENT
C4: Change History
B5: Revision | C5: Description | D5: Date | E5: Modified by
B6: Initial | C6: Initial Release | D6: 45175 | E6: Anila John
B7: Revision 1 | C7: Updated BLE & IR calculations | D7: 45446 | E7: Yamen Alimam
B14: Description : Full FW Test Results | E14: Test Remarks
B15: Details | C15: Data
B16: Device under test | C16: Andromeda Staff badge CTX
B17: Badge HW version | C17: CTH-SB760 Rev A
B18: Badge FW version | C18: 41.1.24
B19: Star Version (If Applicable) | C19: S.3.1.27
B20: Time Star Version | C20: S.0.1.197
B21: Core Live Version | C21: 5.15-SP12-GA
B22: Completion date | C22: 45481
B23: FW Support Ticket | C23: AND-1362
B24: FW Release Ticket | C24: AND-845
B25: Status | C25: Completed
B26: Author/Test Engineer | C26: Yamen Alimam / Anila John

Sheet Summary
A1: Assumptions | H1: Profile Settings | P1: Battery Life (yrs)
A2: Item | B2: Parameter | D2: Assumption | H2: Predefined Profile: Extreme Response Tags
A3: Profile | B3: Predefined profile settings | D3: Extreme response tags | P3: Motion level | Q3: 900 MHz and BLE | R3: w/ BF1 | S3: Low BLE | T3: BLE only* | U3: 900 MHz only* | V3: *Not yet implemented in firmware
A4: Firmware | B4: Firmware version | D4: V24
A5: Motion | B5: Motion level | D5: 0.38 | E5: =D5*7*24 -> 63.84 | F5: hrs/wk | P5: 0.3 | Q5: 1.33 | R5: 1.35 | S5: 2.03 | T5: 1.41 | U5: 2.07
B6: Motion interrupt interval | D6: 1s
A7: UHF | B7: Star coverage | D7: 0.4 | E7: =D7*7*24 -> 67.2 | F7: hrs/wk | P7: 0.38 | Q7: 1.12 | R7: 1.14 | S7: 1.73 | T7: 1.18 | U7: 1.76
B8: RF retry rate | D8: 1.5 | E8: tries
A9: IR / LF | B9: IR coverage | D9: 0.3 | E9: =D9*7*24 -> 50.4 | F9: hrs/wk | P9: 0.5 | Q9: 0.91 | R9: 0.92 | S9: 1.41 | T9: 0.96 | U9: 1.44
B10: IR transitions | D10: 100 | E10: per day
B11: LF Exciter coverage | D11: 0.03 | E11: =D11*7*24 -> 5.04 | F11: hrs/wk
B12: Door Controller coverage | D12: 0 | E12: =D12*7*24 -> 0 | F12: hrs/wk
B13: IR + LF coverage | D13: 0.02 | E13: =D13*7*24 -> 3.36 | F13: hrs/wk
A14: I/O | B14: Button press events | D14: 6 | E14: per day
B15: Duress events | D15: 2 | E15: per day
A16: BLE | B16: Sessions connected to mobile app | D16: 20 | E16: per year
B17: Time connected to app per session | D17: 180s
B18: Duress events | D18: 2 | E18: per day
B19: Duress timeouts | D19: =50/365.25 -> 0.13689254 | E19: per day
B20: Upgrades | D20: 5 | E20: per year
A21: Storage | B21: Shelf time | D21: 6mo
A22: DC-DC | D22: Current draw was measured with 3v input supply. Efficiency can vary with input.

Sheet Calculator
B1: Badge Settings & Assumptions
B2: Operating Mode | C2: 900 MHz and BLE
B3: Tag with Supercapacitor | C3: FALSE | J3: Lifetime | N3: Battery | O3: Nominal Capacity (mAh)
B4: Tag with Proximity Sensor | C4: FALSE | J4: Battery Type | K4: CR2032 | N4: CR2032 | O4: 220
B5: IR Report Rate | C5: 48000 | D5: ms | J5: Nominal Battery Capacity | K5: =IF($K$4=Lists!$A$47,Lists!$B$47,IF($K$4=Lists!$A$48,Lists!$B$48,IF($K$4=Lists!$A$49,Lists!$B$49,IF($K$4=Lists!$A$50,Lists!$B$50,IF($K$4=Lists!$A$51,Lists!$B$51,IF($K$4=Lists!$A$52,Lists!$B$52,IF($K$4=Lists!$A$53,Lists!$B$53,IF($K$4=Lists!$A$54,Lists!$B$54,IF($K$4=Lists!$A$55,Lists!$B$55))))))))) -> 220 | L5: mAh | N5: CR2032H | O5: 240
B6: RF Report Rate | C6: 24000 | D6: ms | J6: # of Batteries in Pack | K6: 3 | N6: CR2430 | O6: 285
B7: IR Profile | C7: 3 | D7: s | J7: Nominal Battery Pack Capacity | K7: =520*1.3 -> 676 | N7: CR2450N | O7: 540
B8: IR-RX | C8: 0 | J8: Derating (Considering Storage) | K8: =C50 -> 0.040147929 | N8: CR2450 | O8: 620
B9: Paging Profile | C9: 24500 | D9: ms | J9: Derated Capacity | K9: =K7*(100%-K8) -> 648.86 | L9: mAh | N9: CR2477 | O9: 950
B10: Proximity Sensor Rate | C10: N/a | D10: ms | N10: ER32L65 | O10: 1000
B11: LF Receive | C11: TRUE | D11: (TRUE/FALSE) | J11: Capacity Cost per Day | K11: =K15*24 -> 1.5213619 | L11: mAh | N11: 1/2AA | O11: 1200
B12: LF Exciter TX Rate | C12: 1000 | D12: ms | K12: =K11/K9 -> 0.0023446689 | L12: Per Day | N12: CR123A | O12: 1500
B13: Door Controller TX Rate | C13: 250 | D13: ms
B14: Security Solutions Mode | C14: FALSE | D14: (TRUE/FALSE) | J14: Average Total Current (Supply Powered) | K14: =C67+C76+C101+C125+C168+C205+C218+C249+C279+C289+C314+C359+C369+C379+C389+C399+C409+C419+C429 -> 0.062618917 | L14: mA
B15: Activity Level (Motion) | C15: 0.38 | D15: =100%-C15 -> 0.62 | E15: Sleep | G15: =$C$15*7*24 -> 63.84 | H15: Hours per Week | J15: Average Total Current (Battery Powered) | K15: =C59+C67+C76+C101+C125+C168+C205+C218+C249+C279+C289+C314+C359+C369+C379+C389+C399+C409+C419+C429 -> 0.063390078 | L15: mA
B16: Motion interrupt interval | C16: 1000 | D16: ms
B17: Star Coverage | C17: 0.4 | D17: =100%-C17 -> 0.6 | E17: Paging Activity | G17: =$C$17*7*24 -> 67.2 | H17: Hours per Week
B18: RF Retry Rate | C18: 1.5 | J18: Lifetime | K18: =K7/K15/24/365.25 -> 1.2165331 | L18: Years
B19: IR Coverage | C19: 0.3 | G19: =$C$19*7*24 -> 50.4 | H19: Hours per Week | J19: Derated Lifetime | K19: =K9/K15/24/365.25 -> 1.1676919 | L19: Years
B20: IR Transitions | C20: 100 | D20: Per Day | K20: =K19*12 -> 14.012302 | L20: Months
B21: LF Exciter Coverage | C21: 0.03 | G21: =$C$21*7*24 -> 5.04 | H21: Hours per Week
B22: Door Controller Coverage | C22: 0 | E22: not yet supported by badge | G22: =$C$22*7*24 -> 0 | H22: Hours per Week
B23: IR + LF Coverage | C23: 0.02 | G23: =$C$23*7*24 -> 3.36 | H23: Hours per Week
B24: Button + RF Location + BLE Transitions+1 Blue LED Blink | C24: 3 | D24: Per Day
B25: Button + RF Location + BLE Transitions+IR + 2 Blue LEDs Blink | C25: 3 | D25: Per Day
B26: Duress Events | C26: 2 | D26: Per Day
J27: Battery Consumers | M27: BLE
J28: BLE | K28: =$E$314+$E$359+$E$389+$E$399+$E$409+$E$419 -> 0.33763052 | M28: Average Total Current | N28: =C314+C359+C389+C399+C409+C419 -> 0.021402425 | O28: mA
J29: IR Receive | K29: =$E$168+$E$205 -> 0.36838173
B30: BLE Parameters | J30: Sleep | K30: =$E$67 -> 0.17615375 | M30: Advertisement | N30: =C314/N28 -> 0.9685274
B31: BLE in 900 MHz | C31: TRUE | E31: not yet supported in estimation | J31: Paging Request & response | K31: =$E$76 -> 0.041131739 | M31: Connection | N31: =C359/N28 -> 0.0045696758
B32: BLE IR-RX profile | C32: 0 | J32: LF | K32: =$E$218 -> 0.026801038 | M32: Duress Event | N32: =C389/N28 -> 0.00025134465
B33: Number of pings | C33: 5 | J33: Motion interrupt | K33: =$E$429 -> 0.017310001 | M33: Duress Timeout | N33: =C409/N28 -> 0.0011350169
B34: First ping optimized? | C34: FALSE | J34: Location Data | K34: =$E$125 -> 0.014977872 | M34: Upgrade | N34: =C399/N28 -> 0.00073769172
B35: Active report rate in BLE | C35: 3000 | D35: ms | J35: Battery Leakage | K35: =$E$59 -> 0.012165331 | M35: Fast Reporting | N35: =C419/N28 -> 0.024778872
B36: Sleep report rate in BLE | C36: 300000 | D36: ms | J36: LBI + Temperature Check | K36: =$E$369+$E$379 -> 0.0044518224 | N36: =SUM(N30:N35) -> 1
B37: Duress Rate | C37: 1000 | D37: ms | E37: not yet supported in estimation | J37: Button Press | K37: =$E$279+$E$289 -> 0.00099619609
B38: Duress Timeout | C38: 60000 | D38: ms | J38: DC field WPS | K38: =$E$249 -> 0
B39: Fast Reporting Rate | C39: 21600 | D39: s | J39: Proximity Check | K39: =$E$101 -> 0
B40: No. of Sessions Connected to Mobile App | C40: 20 | D40: Per Year | J40: TOTAL | K40: =SUM(K28:K39) -> 1
...

Sheet Current Consumption
A1: Factory / Inventory Sleep (Includes LF Check every 2 minutes)
M2: Factory Sleep | N2: Value | O2: Unit
M3: Average Current | N3: 0.0055 | O3: mA
A6: Factory sleep | J6: LF check every 2 minutes
A56: Awake Sleep (Inactive - Between Paging Requests)
M58: Awake Sleep (Inactive) | N58: Value | O58: Unit
M59: Current | N59: 0.00536 | O59: mA
A112: Awake Sleep (Inactive - Between 5min LocationTx)
M114: Awake Sleep (Inactive) | N114: Value | O114: Unit
M115: Current | N115: 0.0054 | O115: mA
A167: Awake Sleep with LF Disabled (Active - Between IR)
B168: 1 | C168: 2 | D168: 3 | E168: 4 | F168: 5 | G168: AVG
A169: Average Current (mA) | B169: 0.01795 | C169: 0.01913 | D169: 0.01536 | E169: 0.01753 | F169: 0.01533 | G169: =AVERAGE(B169:F169) -> 0.01706
A223: Awake Sleep with LF Enabled (Active - Between IR)
B224: 1 | C224: 2 | D224: 3 | E224: 4 | F224: 5 | G224: AVG
A225: Average Current (mA) | B225: 0.02283 | C225: 0.01901 | D225: 0.02123 | E225: 0.01912 | F225: 0.02101 | G225: =AVERAGE(B225:F225) -> 0.02064
A279: Page Request (Without Response)
M282: Page Reqest and Response | N282: Value | O282: Unit
M283: Average current per pulse | N283: 6.45106 | O283: mA
M284: Average Time per pulse | N284: 21.8523 | O284: ms
A336: Paging Interval pairs
A337: REG motion
M340: Page Reqest and Response | N340: Value | O340: Unit
M341: Average current per pulse | N341: 0.07804 | O341: mA
M342: Average Time per pulse | N342: 6085.96 | O342: ms
A398: Paging Interval REG sleep
M401: Page Reqest and Response | N401: Value | O401: Unit
M402: Average current per pulse | N402: 0.006 | O402: mA
M403: Average Time per pulse | N403: 300727 | O403: ms
A453: Paging Interval REG motion
M456: Page Reqest and Response | N456: Value | O456: Unit
M457: Average current per pulse | N457: 0.07901 | O457: mA
M458: Average Time per pulse | N458: 24518.9 | O458: ms
A507: Location Data
M511: RF Location Tx | N511: Value | O511: Unit
M512: Average current | N512: 6.3018 | O512: mA
M513: Average Time per pulse | N513: 16.286 | O513: ms
A558: UHF Location Data Interval (Regular mode, sleep, no IR, no LF)
B559: 1
A560: Average Current (mA) | B560: 0.006
...

Sheet BLE Advertisement
A2: V4 default 5 pings 100ms interval | AK2: V23 default 5 pings 100ms interval | BP2: V4 modified First 2 pings | CP2: mA | CQ2: ms | CU2: V4 modified First 3 pings | DU2: mA | DV2: ms | DZ2: V4 modified First 4 pings | EZ2: mA | FA2: ms | FD2: V4 modified First ping | GD2: mA | GE2: ms | GI2: V4 modified First ping reduced | HI2: mA | HJ2: ms
CP3: 0.69332 | CQ3: 127.8 | DU3: 0.49949 | DV3: 233.83 | EZ3: 0.48753 | FA3: 328.265 | GD3: 3.87051 | GE3: 13.7572 | HI3: 3.82169 | HJ3: 11.5009
CP4: 0.60974 | CQ4: 136.716 | DU4: 0.53705 | DV4: 231.556 | EZ4: 0.44429 | FA4: 333.208 | GD4: 3.77437 | GE4: 14.1362 | HI4: 3.78999 | HJ4: 11.8418
CP5: 0.7552 | CQ5: 118.762 | DU5: 0.537 | DV5: 219.918 | EZ5: 0.48153 | FA5: 339.16 | GD5: 4.26409 | GE5: 14.8057 | HI5: 4.11035 | HJ5: 12.1331
CP6: =AVERAGE(CP3:CP5) -> 0.68608667 | CQ6: =AVERAGE(CQ3:CQ5) -> 127.75933 | DU6: =AVERAGE(DU3:DU5) -> 0.52451333 | DV6: =AVERAGE(DV3:DV5) -> 228.43467 | EZ6: =AVERAGE(EZ3:EZ5) -> 0.47111667 | FA6: =AVERAGE(FA3:FA5) -> 333.54433 | GD6: =AVERAGE(GD3:GD5) -> 3.9696567 | GE6: =AVERAGE(GE3:GE5) -> 14.233033 | HI6: =AVERAGE(HI3:HI5) -> 3.9073433 | HJ6: =AVERAGE(HJ3:HJ5) -> 11.825267
AE11: V4 | AH11: V23
AE12: mA | AF12: ms | AH12: mA | AI12: ms
AE13: 0.43168 | AF13: 443.548 | AH13: 0.56215 | AI13: 442.524
AE14: 0.41137 | AF14: 440.443 | AH14: 0.57317 | AI14: 455.367
AE15: 0.43673 | AF15: 450.124 | AH15: 0.5605 | AI15: 446.637
AE16: =AVERAGE(AE13:AE15) -> 0.42659333 | AF16: =AVERAGE(AF13:AF15) -> 444.705 | AH16: =AVERAGE(AH13:AH15) -> 0.56527333 | AI16: =AVERAGE(AI13:AI15) -> 448.176
AG23: from V23 to V4:
AG24: =(AE16-AH16)/AH16 -> -0.24533264

Sheet Current Sims
A1: Current Simulations
A3: Test FW | B3: V6
A4: Test Profiles | B4: DEFAULT | C4: predefined profile (extreme response tags)
B5: LOW BLE | C5: predefined profile (extreme response tags) 1 ping, 48s active report rate, 1h sleep report rate, 6h fast reporting interval, BLE in 900MHz disabled
A6: Assumptions | B6: Star coverage | C6: Paging | D6: 0.6
C7: In System | D7: =1-D6 -> 0.4
B8: Motion level | C8: Motion | D8: 0.38
C9: Sleep | D9: =1-D8 -> 0.62
B10: IR coverage | C10: IR | D10: 0.3
C11: No IR | D11: =1-D10 -> 0.7
A12: Modes | B12: 1 | C12: async, sleep | D12: =$D$6*$D$9 -> 0.372 | E12: Note: These modes do not include incremental current consumers (i.e. LF receive, button press, battery derating, etc.)
B13: 2 | C13: async, motion | D13: =$D$6*$D$8 -> 0.228
B14: 3 | C14: sync, sleep | D14: =$D$7*$D$9 -> 0.248
B15: 4 | C15: sync, motion, no IR | D15: =$D$7*$D$8*$D$11 -> 0.1064
B16: 5 | C16: sync, motion, IR | D16: =$D$7*$D$8*$D$10 -> 0.0456
A18: Results
A19: HW | B19: Tag ID | C19: Tester | D19: FW | E19: Profile | F19: Modes | K19: Average Current (uA) | L19: Battery Life (yrs) | M19: Comments
F20: 1 | G20: 2 | H20: 3 | I20: 4 | J20: 5
A21: Rev 0 | C21: Yamen | D21: V6 | E21: DEFAULT | F21: 9.52 | G21: 155.85 | H21: 9.24 | I21: 120.35 | J21: 68.04 | K21: =F21*$D$12+G21*$D$13+H21*$D$14+I21*$D$15+J21*$D$16 -> 57.274624 | L21: =675/(K21*10^-3)/24/365 -> 1.3453566
A22: Rev 0 | C22: Yamen | D22: V6 | E22: LOW BLE | F22: 7.72 | G22: 107.05 | H22: 5.79 | I22: 72.75 | J22: 65.79 | K22: =F22*$D$12+G22*$D$13+H22*$D$14+I22*$D$15+J22*$D$16 -> 39.455784 | L22: =675/(K22*10^-3)/24/365 -> 1.9529404
A23: Rev A | B23: 17724301 | C23: Anila | D23: V24A | E23: DEFAULT | F23: 11.8 | G23: 171.8 | H23: 11.07 | I23: 126.5 | J23: 79.59 | K23: =F23*$D$12+G23*$D$13+H23*$D$14+I23*$D$15+J23*$D$16 -> 63.394264 | L23: =675/(K23*10^-3)/24/365 -> 1.2154853
A24: Rev A | B24: 17724301 | C24: Yamen | D24: V24A | E24: DEFAULT | F24: 11.59 | G24: 168.26 | H24: 10.89 | I24: 125.63 | J24: 71.35 | K24: =F24*$D$12+G24*$D$13+H24*$D$14+I24*$D$15+J24*$D$16 -> 61.996072 | L24: =675/(K24*10^-3)/24/365 -> 1.242898 | M24: does not include hourly BLE fast report; due to HW tolerances, acceptable current values fall within a range
A25: Rev A | B25: 17724338 | C25: Yamen | D25: V24A | E25: DEFAULT | G25: 164.56 | H25: 7.11 | I25: 120.18 | K25: =F25*$D$12+G25*$D$13+H25*$D$14+I25*$D$15+J25*$D$16 -> 52.070112 | L25: =675/(K25*10^-3)/24/365 -> 1.4798277 | M25: does not include hourly BLE fast report, V24A and test V6 are comparable in terms of current consumption
A26: Rev A | B26: 17724338 | C26: Yamen | D26: V6 | E26: DEFAULT | G26: 165.94 | I26: 123.18 | K26: =F26*$D$12+G26*$D$13+H26*$D$14+I26*$D$15+J26*$D$16 -> 50.940672 | L26: =675/(K26*10^-3)/24/365 -> 1.512638

Sheet BF1
A1: V10 – Initial Peak duration: 3.91ms and current 4.75mA
L3: mA | M3: ms | N3: mA*ms
L4: 4.75 | M4: 3.91 | N4: =L4*M4 -> 18.5725 | Q4: mA | R4: ms | S4: mA*ms
P5: 5 ping burst | Q5: ='[2]BLE Advertisement'!AE16 -> 0.42659333 | R5: ='[2]BLE Advertisement'!AF16 -> 444.705 | S5: =Q5*R5 -> 189.70819
P7: reduction in charge | Q7: =N28-N4 -> 10.4101
P9: 5 ping burst (optimized) | Q9: =S9/R9 -> 0.40441201 | R9: =R5-(M28-M4) -> 443.355 | S9: =S5-Q7 -> 179.29809
A25: V09 – Initial Peak duration: 5.26ms and current 5.51mA
L27: mA | M27: ms | N27: mA*ms
L28: 5.51 | M28: 5.26 | N28: =L28*M28 -> 28.9826

Sheet Lists
A1: Active Paging Rate (ms)
A2: 12500
A3: 9500
A4: 6500
A5: 24500
A7: IR Report Rate (ms)
A8: 24000
A9: 48000
A10: 120000
A11: 300000
A13: RF Report Rate (ms)
A14: 6000
A15: 12000
A16: 24000
A17: 48000
A19: IR Profile (s) | B19: Power
A20: 1.5 | B20: LOW
A21: 3 | B21: MEDIUM
A22: 6 | B22: HIGH
A24: LF Power Levels
A25: 1
A26: 2
A27: 3
A29: Battery Cells
A30: 1
A31: 2
A33: Binary
A34: 0 | B34: TRUE
A35: 1 | B35: FALSE
A37: Proximity Sensor Interval (ms)
A38: 250
A39: 500
A40: 1000
A41: 2000
A42: 10000
A43: 30000
A44: 60000
A45: N/a
A47: Battery | B47: Capacity (mAh)
A48: CR2032 | B48: 220
...
